<mujoco model="humanoid_hopper">
    <!-- Simulation Parameters -->
    <option gravity="0 0 -9.81" timestep="0.001" iterations="50"/>
    
    <worldbody>
        <!-- Torso -->
        <body name="torso" pos="0 0 1">
            <geom type="capsule" size="0.1 0.2" rgba="0.8 0.6 0.4 1" />
            <geom type="sphere" size="0.12" pos="0 0 0.2" rgba="0.8 0.6 0.4 1" />
            <joint type="free" name="root" />
            
            <!-- Left Leg -->
            <body name="thigh_left" pos="0 -0.1 -0.2">
                <geom type="capsule" fromto="0 0 0 0 0 -0.4" size="0.05" rgba="0.5 0.5 0.5 1" />
                <joint type="hinge" name="hip_left" axis="0 1 0" range="-30 30" damping="0.1" stiffness="0.1"/>
                <body name="leg_left" pos="0 0 -0.4">
                    <geom type="capsule" fromto="0 0 0 0 0 -0.4" size="0.04" rgba="0.7 0.7 0.7 1" />
                    <joint type="hinge" name="knee_left" axis="0 1 0" range="30 150" damping="0.1" stiffness="0.1"/>
                    <body name="foot_left" pos="0 0 -0.4">
                        <geom type="box" size="0.1 0.05 0.02" rgba="0.3 0.3 0.3 1" friction="1 0.1 0.1"/>
                        <joint type="hinge" name="ankle_left" axis="0 1 0" range="-20 20" damping="0.1" stiffness="0.1" /> 
                    </body>
                </body>
            </body>
            
            <!-- Right Leg -->
            <body name="thigh_right" pos="0 0.1 -0.2">
                <geom type="capsule" fromto="0 0 0 0 0 -0.4" size="0.05" rgba="0.5 0.5 0.5 1" />
                <joint type="hinge" name="hip_right" axis="0 1 0" range="-30 30" damping="0.1" stiffness="0.1"/>
                <body name="leg_right" pos="0 0 -0.4">
                    <geom type="capsule" fromto="0 0 0 0 0 -0.4" size="0.04" rgba="0.7 0.7 0.7 1" />
                    <joint type="hinge" name="knee_right" axis="0 1 0" range="30 150" damping="0.1" stiffness="0.1"/>
                    <body name="foot_right" pos="0 0 -0.4">
                        <geom type="box" size="0.1 0.05 0.02" rgba="0.3 0.3 0.3 1" friction="1 0.1 0.1"/>
                        <joint type="hinge" name="ankle_right" axis="0 1 0" range="-20 20" damping="0.1" stiffness="0.1" /> 
                    </body>
                </body>
            </body>
        </body>

        <!-- Ground Plane -->
        <body name="ground" pos="0 0 0">
            <geom type="plane" size="10 10 0.1" rgba="0.7 0.7 0.7 1" />
        </body>

    </worldbody>
    
    <!-- Actuators -->
    <actuator>
        <!-- Left Leg Motors -->
        <motor joint="hip_left" gear="100" />
        <motor joint="knee_left" gear="100" />
        <motor joint="ankle_left" gear="50" />  
        
        <!-- Right Leg Motors -->
        <motor joint="hip_right" gear="100" />
        <motor joint="knee_right" gear="100" />
        <motor joint="ankle_right" gear="50" />  
    </actuator>

    <!-- Sensors for Feedback -->
    <sensor>
        <!-- Joint Position Sensors -->
        <jointpos joint="hip_left" />
        <jointpos joint="knee_left" />
        <jointpos joint="ankle_left" />
        <jointpos joint="hip_right" />
        <jointpos joint="knee_right" />
        <jointpos joint="ankle_right" />
        
        <!-- Joint Velocity Sensors -->
        <jointvel joint="hip_left" />
        <jointvel joint="knee_left" />
        <jointvel joint="ankle_left" />
        <jointvel joint="hip_right" />
        <jointvel joint="knee_right" />
        <jointvel joint="ankle_right" />
    </sensor>
</mujoco>